[2023-11-08T19:35:28.259+0300] {taskinstance.py:1159} INFO - Dependencies all met for dep_context=non-requeueable deps ti=<TaskInstance: my_task_score.get_data manual__2023-11-08T16:35:09.280505+00:00 [queued]>
[2023-11-08T19:35:28.385+0300] {taskinstance.py:1159} INFO - Dependencies all met for dep_context=requeueable deps ti=<TaskInstance: my_task_score.get_data manual__2023-11-08T16:35:09.280505+00:00 [queued]>
[2023-11-08T19:35:28.385+0300] {taskinstance.py:1361} INFO - Starting attempt 1 of 2
[2023-11-08T19:35:29.190+0300] {taskinstance.py:1382} INFO - Executing <Task(BashOperator): get_data> on 2023-11-08 16:35:09.280505+00:00
[2023-11-08T19:35:29.293+0300] {standard_task_runner.py:57} INFO - Started process 34262 to run task
[2023-11-08T19:35:29.336+0300] {standard_task_runner.py:84} INFO - Running: ['airflow', 'tasks', 'run', 'my_task_score', 'get_data', 'manual__2023-11-08T16:35:09.280505+00:00', '--job-id', '22', '--raw', '--subdir', 'DAGS_FOLDER/run_airflow.py', '--cfg-path', '/tmp/tmpxvcnoxql']
[2023-11-08T19:35:29.362+0300] {standard_task_runner.py:85} INFO - Job 22: Subtask get_data
[2023-11-08T19:35:31.676+0300] {task_command.py:416} INFO - Running <TaskInstance: my_task_score.get_data manual__2023-11-08T16:35:09.280505+00:00 [running]> on host MLOPS-3-3.myguest.virtualbox.org
[2023-11-08T19:35:33.106+0300] {taskinstance.py:1662} INFO - Exporting env vars: AIRFLOW_CTX_DAG_OWNER='admin' AIRFLOW_CTX_DAG_ID='my_task_score' AIRFLOW_CTX_TASK_ID='get_data' AIRFLOW_CTX_EXECUTION_DATE='2023-11-08T16:35:09.280505+00:00' AIRFLOW_CTX_TRY_NUMBER='1' AIRFLOW_CTX_DAG_RUN_ID='manual__2023-11-08T16:35:09.280505+00:00'
[2023-11-08T19:35:33.139+0300] {subprocess.py:63} INFO - Tmp dir root location: /tmp
[2023-11-08T19:35:33.159+0300] {subprocess.py:75} INFO - Running command: ['/usr/bin/bash', '-c', 'python3 /home/petr/project/scripts/get_data.py']
[2023-11-08T19:35:33.422+0300] {subprocess.py:86} INFO - Output:
[2023-11-08T19:35:40.014+0300] {subprocess.py:93} INFO - /home/petr/project/venv/lib/python3.10/site-packages/pydantic/_internal/_fields.py:128: UserWarning: Field "model_server_url" has conflict with protected namespace "model_".
[2023-11-08T19:35:40.014+0300] {subprocess.py:93} INFO - 
[2023-11-08T19:35:40.015+0300] {subprocess.py:93} INFO - You may be able to resolve this warning by setting `model_config['protected_namespaces'] = ()`.
[2023-11-08T19:35:40.015+0300] {subprocess.py:93} INFO -   warnings.warn(
[2023-11-08T19:35:40.128+0300] {subprocess.py:93} INFO - /home/petr/project/venv/lib/python3.10/site-packages/pydantic/_internal/_config.py:317: UserWarning: Valid config keys have changed in V2:
[2023-11-08T19:35:40.128+0300] {subprocess.py:93} INFO - * 'schema_extra' has been renamed to 'json_schema_extra'
[2023-11-08T19:35:40.128+0300] {subprocess.py:93} INFO -   warnings.warn(message, UserWarning)
[2023-11-08T19:35:40.165+0300] {subprocess.py:93} INFO - Traceback (most recent call last):
[2023-11-08T19:35:40.166+0300] {subprocess.py:93} INFO -   File "/home/petr/project/scripts/get_data.py", line 20, in <module>
[2023-11-08T19:35:40.166+0300] {subprocess.py:93} INFO -     mlflow.set_tracking_uri("http://localhost:5000")
[2023-11-08T19:35:40.166+0300] {subprocess.py:93} INFO - NameError: name 'mlflow' is not defined
[2023-11-08T19:35:41.026+0300] {subprocess.py:97} INFO - Command exited with return code 1
[2023-11-08T19:35:41.104+0300] {taskinstance.py:1937} ERROR - Task failed with exception
Traceback (most recent call last):
  File "/home/petr/project/venv/lib/python3.10/site-packages/airflow/operators/bash.py", line 210, in execute
    raise AirflowException(
airflow.exceptions.AirflowException: Bash command failed. The command returned a non-zero exit code 1.
[2023-11-08T19:35:41.137+0300] {taskinstance.py:1400} INFO - Marking task as UP_FOR_RETRY. dag_id=my_task_score, task_id=get_data, execution_date=20231108T163509, start_date=20231108T163528, end_date=20231108T163541
[2023-11-08T19:35:41.210+0300] {standard_task_runner.py:104} ERROR - Failed to execute job 22 for task get_data (Bash command failed. The command returned a non-zero exit code 1.; 34262)
[2023-11-08T19:35:41.289+0300] {local_task_job_runner.py:228} INFO - Task exited with return code 1
[2023-11-08T19:35:41.573+0300] {taskinstance.py:2778} INFO - 0 downstream tasks scheduled from follow-on schedule check
