[2023-11-08T19:29:24.957+0300] {taskinstance.py:1159} INFO - Dependencies all met for dep_context=non-requeueable deps ti=<TaskInstance: my_task_score.get_data manual__2023-11-08T16:14:28.232652+00:00 [queued]>
[2023-11-08T19:29:25.073+0300] {taskinstance.py:1159} INFO - Dependencies all met for dep_context=requeueable deps ti=<TaskInstance: my_task_score.get_data manual__2023-11-08T16:14:28.232652+00:00 [queued]>
[2023-11-08T19:29:25.085+0300] {taskinstance.py:1361} INFO - Starting attempt 2 of 2
[2023-11-08T19:29:26.056+0300] {taskinstance.py:1382} INFO - Executing <Task(BashOperator): get_data> on 2023-11-08 16:14:28.232652+00:00
[2023-11-08T19:29:26.080+0300] {standard_task_runner.py:57} INFO - Started process 33009 to run task
[2023-11-08T19:29:26.116+0300] {standard_task_runner.py:84} INFO - Running: ['airflow', 'tasks', 'run', 'my_task_score', 'get_data', 'manual__2023-11-08T16:14:28.232652+00:00', '--job-id', '21', '--raw', '--subdir', 'DAGS_FOLDER/run_airflow.py', '--cfg-path', '/tmp/tmpw58hza2h']
[2023-11-08T19:29:26.118+0300] {standard_task_runner.py:85} INFO - Job 21: Subtask get_data
[2023-11-08T19:29:26.922+0300] {task_command.py:416} INFO - Running <TaskInstance: my_task_score.get_data manual__2023-11-08T16:14:28.232652+00:00 [running]> on host MLOPS-3-3.myguest.virtualbox.org
[2023-11-08T19:29:27.548+0300] {taskinstance.py:1662} INFO - Exporting env vars: AIRFLOW_CTX_DAG_OWNER='admin' AIRFLOW_CTX_DAG_ID='my_task_score' AIRFLOW_CTX_TASK_ID='get_data' AIRFLOW_CTX_EXECUTION_DATE='2023-11-08T16:14:28.232652+00:00' AIRFLOW_CTX_TRY_NUMBER='2' AIRFLOW_CTX_DAG_RUN_ID='manual__2023-11-08T16:14:28.232652+00:00'
[2023-11-08T19:29:27.550+0300] {subprocess.py:63} INFO - Tmp dir root location: /tmp
[2023-11-08T19:29:27.572+0300] {subprocess.py:75} INFO - Running command: ['/usr/bin/bash', '-c', 'python3 /home/petr/project/scripts/get_data.py']
[2023-11-08T19:29:27.626+0300] {subprocess.py:86} INFO - Output:
[2023-11-08T19:29:33.359+0300] {subprocess.py:93} INFO - /home/petr/project/venv/lib/python3.10/site-packages/pydantic/_internal/_fields.py:128: UserWarning: Field "model_server_url" has conflict with protected namespace "model_".
[2023-11-08T19:29:33.360+0300] {subprocess.py:93} INFO - 
[2023-11-08T19:29:33.360+0300] {subprocess.py:93} INFO - You may be able to resolve this warning by setting `model_config['protected_namespaces'] = ()`.
[2023-11-08T19:29:33.360+0300] {subprocess.py:93} INFO -   warnings.warn(
[2023-11-08T19:29:33.444+0300] {subprocess.py:93} INFO - /home/petr/project/venv/lib/python3.10/site-packages/pydantic/_internal/_config.py:317: UserWarning: Valid config keys have changed in V2:
[2023-11-08T19:29:33.445+0300] {subprocess.py:93} INFO - * 'schema_extra' has been renamed to 'json_schema_extra'
[2023-11-08T19:29:33.445+0300] {subprocess.py:93} INFO -   warnings.warn(message, UserWarning)
[2023-11-08T19:29:33.475+0300] {subprocess.py:93} INFO - Traceback (most recent call last):
[2023-11-08T19:29:33.475+0300] {subprocess.py:93} INFO -   File "/home/petr/project/scripts/get_data.py", line 20, in <module>
[2023-11-08T19:29:33.475+0300] {subprocess.py:93} INFO -     mlflow.set_tracking_uri("http://localhost:5000")
[2023-11-08T19:29:33.475+0300] {subprocess.py:93} INFO - NameError: name 'mlflow' is not defined
[2023-11-08T19:29:34.266+0300] {subprocess.py:97} INFO - Command exited with return code 1
[2023-11-08T19:29:34.304+0300] {taskinstance.py:1937} ERROR - Task failed with exception
Traceback (most recent call last):
  File "/home/petr/project/venv/lib/python3.10/site-packages/airflow/operators/bash.py", line 210, in execute
    raise AirflowException(
airflow.exceptions.AirflowException: Bash command failed. The command returned a non-zero exit code 1.
[2023-11-08T19:29:34.317+0300] {taskinstance.py:1400} INFO - Marking task as FAILED. dag_id=my_task_score, task_id=get_data, execution_date=20231108T161428, start_date=20231108T162924, end_date=20231108T162934
[2023-11-08T19:29:34.354+0300] {standard_task_runner.py:104} ERROR - Failed to execute job 21 for task get_data (Bash command failed. The command returned a non-zero exit code 1.; 33009)
[2023-11-08T19:29:34.389+0300] {local_task_job_runner.py:228} INFO - Task exited with return code 1
[2023-11-08T19:29:34.459+0300] {taskinstance.py:2778} INFO - 0 downstream tasks scheduled from follow-on schedule check
