[2023-11-08T19:57:24.362+0300] {taskinstance.py:1159} INFO - Dependencies all met for dep_context=non-requeueable deps ti=<TaskInstance: my_task_score.get_data manual__2023-11-08T16:51:43.431782+00:00 [queued]>
[2023-11-08T19:57:24.481+0300] {taskinstance.py:1159} INFO - Dependencies all met for dep_context=requeueable deps ti=<TaskInstance: my_task_score.get_data manual__2023-11-08T16:51:43.431782+00:00 [queued]>
[2023-11-08T19:57:24.482+0300] {taskinstance.py:1361} INFO - Starting attempt 2 of 2
[2023-11-08T19:57:26.195+0300] {taskinstance.py:1382} INFO - Executing <Task(BashOperator): get_data> on 2023-11-08 16:51:43.431782+00:00
[2023-11-08T19:57:26.212+0300] {standard_task_runner.py:57} INFO - Started process 38661 to run task
[2023-11-08T19:57:26.297+0300] {standard_task_runner.py:84} INFO - Running: ['airflow', 'tasks', 'run', 'my_task_score', 'get_data', 'manual__2023-11-08T16:51:43.431782+00:00', '--job-id', '27', '--raw', '--subdir', 'DAGS_FOLDER/run_airflow.py', '--cfg-path', '/tmp/tmpizcgys6p']
[2023-11-08T19:57:26.313+0300] {standard_task_runner.py:85} INFO - Job 27: Subtask get_data
[2023-11-08T19:57:27.321+0300] {task_command.py:416} INFO - Running <TaskInstance: my_task_score.get_data manual__2023-11-08T16:51:43.431782+00:00 [running]> on host MLOPS-3-3.myguest.virtualbox.org
[2023-11-08T19:57:28.108+0300] {taskinstance.py:1662} INFO - Exporting env vars: AIRFLOW_CTX_DAG_OWNER='admin' AIRFLOW_CTX_DAG_ID='my_task_score' AIRFLOW_CTX_TASK_ID='get_data' AIRFLOW_CTX_EXECUTION_DATE='2023-11-08T16:51:43.431782+00:00' AIRFLOW_CTX_TRY_NUMBER='2' AIRFLOW_CTX_DAG_RUN_ID='manual__2023-11-08T16:51:43.431782+00:00'
[2023-11-08T19:57:28.109+0300] {subprocess.py:63} INFO - Tmp dir root location: /tmp
[2023-11-08T19:57:28.140+0300] {subprocess.py:75} INFO - Running command: ['/usr/bin/bash', '-c', 'python3 /home/petr/project/scripts/get_data.py']
[2023-11-08T19:57:28.231+0300] {subprocess.py:86} INFO - Output:
[2023-11-08T19:57:29.545+0300] {subprocess.py:93} INFO - Traceback (most recent call last):
[2023-11-08T19:57:29.572+0300] {subprocess.py:93} INFO -   File "/home/petr/project/scripts/get_data.py", line 11, in <module>
[2023-11-08T19:57:29.574+0300] {subprocess.py:93} INFO -     from github import Github
[2023-11-08T19:57:29.574+0300] {subprocess.py:93} INFO - ImportError: cannot import name 'Github' from 'github' (/home/petr/project/venv/lib/python3.10/site-packages/github/__init__.py)
[2023-11-08T19:57:29.850+0300] {subprocess.py:97} INFO - Command exited with return code 1
[2023-11-08T19:57:30.140+0300] {taskinstance.py:1937} ERROR - Task failed with exception
Traceback (most recent call last):
  File "/home/petr/project/venv/lib/python3.10/site-packages/airflow/operators/bash.py", line 210, in execute
    raise AirflowException(
airflow.exceptions.AirflowException: Bash command failed. The command returned a non-zero exit code 1.
[2023-11-08T19:57:30.218+0300] {taskinstance.py:1400} INFO - Marking task as FAILED. dag_id=my_task_score, task_id=get_data, execution_date=20231108T165143, start_date=20231108T165724, end_date=20231108T165730
[2023-11-08T19:57:30.477+0300] {standard_task_runner.py:104} ERROR - Failed to execute job 27 for task get_data (Bash command failed. The command returned a non-zero exit code 1.; 38661)
[2023-11-08T19:57:30.552+0300] {local_task_job_runner.py:228} INFO - Task exited with return code 1
[2023-11-08T19:57:30.819+0300] {taskinstance.py:2778} INFO - 0 downstream tasks scheduled from follow-on schedule check
