[2023-11-08T21:50:51.654+0300] {taskinstance.py:1159} INFO - Dependencies all met for dep_context=non-requeueable deps ti=<TaskInstance: my_task_score.get_data manual__2023-11-08T18:50:44.563762+00:00 [queued]>
[2023-11-08T21:50:51.828+0300] {taskinstance.py:1159} INFO - Dependencies all met for dep_context=requeueable deps ti=<TaskInstance: my_task_score.get_data manual__2023-11-08T18:50:44.563762+00:00 [queued]>
[2023-11-08T21:50:51.828+0300] {taskinstance.py:1361} INFO - Starting attempt 1 of 2
[2023-11-08T21:50:51.873+0300] {taskinstance.py:1382} INFO - Executing <Task(BashOperator): get_data> on 2023-11-08 18:50:44.563762+00:00
[2023-11-08T21:50:51.877+0300] {standard_task_runner.py:57} INFO - Started process 5477 to run task
[2023-11-08T21:50:51.895+0300] {standard_task_runner.py:84} INFO - Running: ['airflow', 'tasks', 'run', 'my_task_score', 'get_data', 'manual__2023-11-08T18:50:44.563762+00:00', '--job-id', '32', '--raw', '--subdir', 'DAGS_FOLDER/run_airflow.py', '--cfg-path', '/tmp/tmpcas4y9ys']
[2023-11-08T21:50:51.897+0300] {standard_task_runner.py:85} INFO - Job 32: Subtask get_data
[2023-11-08T21:50:52.144+0300] {task_command.py:416} INFO - Running <TaskInstance: my_task_score.get_data manual__2023-11-08T18:50:44.563762+00:00 [running]> on host MLOPS-3-3.myguest.virtualbox.org
[2023-11-08T21:50:52.374+0300] {taskinstance.py:1662} INFO - Exporting env vars: AIRFLOW_CTX_DAG_OWNER='admin' AIRFLOW_CTX_DAG_ID='my_task_score' AIRFLOW_CTX_TASK_ID='get_data' AIRFLOW_CTX_EXECUTION_DATE='2023-11-08T18:50:44.563762+00:00' AIRFLOW_CTX_TRY_NUMBER='1' AIRFLOW_CTX_DAG_RUN_ID='manual__2023-11-08T18:50:44.563762+00:00'
[2023-11-08T21:50:52.376+0300] {subprocess.py:63} INFO - Tmp dir root location: /tmp
[2023-11-08T21:50:52.379+0300] {subprocess.py:75} INFO - Running command: ['/usr/bin/bash', '-c', 'python3 /home/petr/project/scripts/get_data.py']
[2023-11-08T21:50:52.399+0300] {subprocess.py:86} INFO - Output:
[2023-11-08T21:50:53.326+0300] {subprocess.py:93} INFO - WARNING: pip is being invoked by an old script wrapper. This will fail in a future version of pip.
[2023-11-08T21:50:53.326+0300] {subprocess.py:93} INFO - Please see https://github.com/pypa/pip/issues/5599 for advice on fixing the underlying issue.
[2023-11-08T21:50:53.326+0300] {subprocess.py:93} INFO - To avoid this problem you can invoke Python with '-m pip' instead of running pip directly.
[2023-11-08T21:50:53.997+0300] {subprocess.py:93} INFO - Requirement already satisfied: PyGithub in /home/petr/project/venv/lib/python3.10/site-packages (2.1.1)
[2023-11-08T21:50:54.010+0300] {subprocess.py:93} INFO - Requirement already satisfied: urllib3>=1.26.0 in /home/petr/project/venv/lib/python3.10/site-packages (from PyGithub) (2.0.7)
[2023-11-08T21:50:54.020+0300] {subprocess.py:93} INFO - Requirement already satisfied: pynacl>=1.4.0 in /home/petr/project/venv/lib/python3.10/site-packages (from PyGithub) (1.5.0)
[2023-11-08T21:50:54.024+0300] {subprocess.py:93} INFO - Requirement already satisfied: requests>=2.14.0 in /home/petr/project/venv/lib/python3.10/site-packages (from PyGithub) (2.31.0)
[2023-11-08T21:50:54.025+0300] {subprocess.py:93} INFO - Requirement already satisfied: python-dateutil in /home/petr/project/venv/lib/python3.10/site-packages (from PyGithub) (2.8.2)
[2023-11-08T21:50:54.026+0300] {subprocess.py:93} INFO - Requirement already satisfied: pyjwt[crypto]>=2.4.0 in /home/petr/project/venv/lib/python3.10/site-packages (from PyGithub) (2.8.0)
[2023-11-08T21:50:54.028+0300] {subprocess.py:93} INFO - Requirement already satisfied: typing-extensions>=4.0.0 in /home/petr/project/venv/lib/python3.10/site-packages (from PyGithub) (4.8.0)
[2023-11-08T21:50:54.029+0300] {subprocess.py:93} INFO - Requirement already satisfied: Deprecated in /home/petr/project/venv/lib/python3.10/site-packages (from PyGithub) (1.2.14)
[2023-11-08T21:50:54.062+0300] {subprocess.py:93} INFO - Requirement already satisfied: cryptography>=3.4.0 in /home/petr/project/venv/lib/python3.10/site-packages (from pyjwt[crypto]>=2.4.0->PyGithub) (41.0.5)
[2023-11-08T21:50:54.091+0300] {subprocess.py:93} INFO - Requirement already satisfied: cffi>=1.4.1 in /home/petr/project/venv/lib/python3.10/site-packages (from pynacl>=1.4.0->PyGithub) (1.16.0)
[2023-11-08T21:50:54.120+0300] {subprocess.py:93} INFO - Requirement already satisfied: idna<4,>=2.5 in /home/petr/project/venv/lib/python3.10/site-packages (from requests>=2.14.0->PyGithub) (3.4)
[2023-11-08T21:50:54.124+0300] {subprocess.py:93} INFO - Requirement already satisfied: charset-normalizer<4,>=2 in /home/petr/project/venv/lib/python3.10/site-packages (from requests>=2.14.0->PyGithub) (2.1.1)
[2023-11-08T21:50:54.127+0300] {subprocess.py:93} INFO - Requirement already satisfied: certifi>=2017.4.17 in /home/petr/project/venv/lib/python3.10/site-packages (from requests>=2.14.0->PyGithub) (2023.7.22)
[2023-11-08T21:50:54.160+0300] {subprocess.py:93} INFO - Requirement already satisfied: wrapt<2,>=1.10 in /home/petr/project/venv/lib/python3.10/site-packages (from Deprecated->PyGithub) (1.15.0)
[2023-11-08T21:50:54.171+0300] {subprocess.py:93} INFO - Requirement already satisfied: six>=1.5 in /home/petr/project/venv/lib/python3.10/site-packages (from python-dateutil->PyGithub) (1.16.0)
[2023-11-08T21:50:54.177+0300] {subprocess.py:93} INFO - Requirement already satisfied: pycparser in /home/petr/project/venv/lib/python3.10/site-packages (from cffi>=1.4.1->pynacl>=1.4.0->PyGithub) (2.21)
[2023-11-08T21:51:15.139+0300] {subprocess.py:93} INFO - /home/petr/project/venv/lib/python3.10/site-packages/pydantic/_internal/_fields.py:128: UserWarning: Field "model_server_url" has conflict with protected namespace "model_".
[2023-11-08T21:51:15.140+0300] {subprocess.py:93} INFO - 
[2023-11-08T21:51:15.140+0300] {subprocess.py:93} INFO - You may be able to resolve this warning by setting `model_config['protected_namespaces'] = ()`.
[2023-11-08T21:51:15.140+0300] {subprocess.py:93} INFO -   warnings.warn(
[2023-11-08T21:51:15.200+0300] {subprocess.py:93} INFO - /home/petr/project/venv/lib/python3.10/site-packages/pydantic/_internal/_config.py:317: UserWarning: Valid config keys have changed in V2:
[2023-11-08T21:51:15.201+0300] {subprocess.py:93} INFO - * 'schema_extra' has been renamed to 'json_schema_extra'
[2023-11-08T21:51:15.201+0300] {subprocess.py:93} INFO -   warnings.warn(message, UserWarning)
[2023-11-08T21:51:21.372+0300] {subprocess.py:97} INFO - Command exited with return code 0
[2023-11-08T21:51:21.525+0300] {taskinstance.py:1400} INFO - Marking task as SUCCESS. dag_id=my_task_score, task_id=get_data, execution_date=20231108T185044, start_date=20231108T185051, end_date=20231108T185121
[2023-11-08T21:51:21.580+0300] {local_task_job_runner.py:228} INFO - Task exited with return code 0
[2023-11-08T21:51:21.714+0300] {taskinstance.py:2778} INFO - 1 downstream tasks scheduled from follow-on schedule check
