[2023-11-08T19:48:29.761+0300] {taskinstance.py:1159} INFO - Dependencies all met for dep_context=non-requeueable deps ti=<TaskInstance: my_task_score.get_data manual__2023-11-08T16:42:36.923959+00:00 [queued]>
[2023-11-08T19:48:29.897+0300] {taskinstance.py:1159} INFO - Dependencies all met for dep_context=requeueable deps ti=<TaskInstance: my_task_score.get_data manual__2023-11-08T16:42:36.923959+00:00 [queued]>
[2023-11-08T19:48:29.897+0300] {taskinstance.py:1361} INFO - Starting attempt 2 of 2
[2023-11-08T19:48:31.252+0300] {taskinstance.py:1382} INFO - Executing <Task(BashOperator): get_data> on 2023-11-08 16:42:36.923959+00:00
[2023-11-08T19:48:31.272+0300] {standard_task_runner.py:57} INFO - Started process 36886 to run task
[2023-11-08T19:48:31.295+0300] {standard_task_runner.py:84} INFO - Running: ['airflow', 'tasks', 'run', 'my_task_score', 'get_data', 'manual__2023-11-08T16:42:36.923959+00:00', '--job-id', '25', '--raw', '--subdir', 'DAGS_FOLDER/run_airflow.py', '--cfg-path', '/tmp/tmpg0hcf95w']
[2023-11-08T19:48:31.329+0300] {standard_task_runner.py:85} INFO - Job 25: Subtask get_data
[2023-11-08T19:48:32.035+0300] {task_command.py:416} INFO - Running <TaskInstance: my_task_score.get_data manual__2023-11-08T16:42:36.923959+00:00 [running]> on host MLOPS-3-3.myguest.virtualbox.org
[2023-11-08T19:48:32.926+0300] {taskinstance.py:1662} INFO - Exporting env vars: AIRFLOW_CTX_DAG_OWNER='admin' AIRFLOW_CTX_DAG_ID='my_task_score' AIRFLOW_CTX_TASK_ID='get_data' AIRFLOW_CTX_EXECUTION_DATE='2023-11-08T16:42:36.923959+00:00' AIRFLOW_CTX_TRY_NUMBER='2' AIRFLOW_CTX_DAG_RUN_ID='manual__2023-11-08T16:42:36.923959+00:00'
[2023-11-08T19:48:32.928+0300] {subprocess.py:63} INFO - Tmp dir root location: /tmp
[2023-11-08T19:48:32.953+0300] {subprocess.py:75} INFO - Running command: ['/usr/bin/bash', '-c', 'python3 /home/petr/project/scripts/get_data.py']
[2023-11-08T19:48:33.028+0300] {subprocess.py:86} INFO - Output:
[2023-11-08T19:48:39.681+0300] {subprocess.py:93} INFO - /home/petr/project/venv/lib/python3.10/site-packages/pydantic/_internal/_fields.py:128: UserWarning: Field "model_server_url" has conflict with protected namespace "model_".
[2023-11-08T19:48:39.682+0300] {subprocess.py:93} INFO - 
[2023-11-08T19:48:39.682+0300] {subprocess.py:93} INFO - You may be able to resolve this warning by setting `model_config['protected_namespaces'] = ()`.
[2023-11-08T19:48:39.682+0300] {subprocess.py:93} INFO -   warnings.warn(
[2023-11-08T19:48:39.749+0300] {subprocess.py:93} INFO - /home/petr/project/venv/lib/python3.10/site-packages/pydantic/_internal/_config.py:317: UserWarning: Valid config keys have changed in V2:
[2023-11-08T19:48:39.749+0300] {subprocess.py:93} INFO - * 'schema_extra' has been renamed to 'json_schema_extra'
[2023-11-08T19:48:39.749+0300] {subprocess.py:93} INFO -   warnings.warn(message, UserWarning)
[2023-11-08T19:48:39.780+0300] {subprocess.py:93} INFO - Traceback (most recent call last):
[2023-11-08T19:48:39.805+0300] {subprocess.py:93} INFO -   File "/home/petr/project/scripts/get_data.py", line 21, in <module>
[2023-11-08T19:48:39.806+0300] {subprocess.py:93} INFO -     mlflow.set_tracking_uri("http://localhost:5000")
[2023-11-08T19:48:39.806+0300] {subprocess.py:93} INFO - NameError: name 'mlflow' is not defined
[2023-11-08T19:48:40.697+0300] {subprocess.py:97} INFO - Command exited with return code 1
[2023-11-08T19:48:40.810+0300] {taskinstance.py:1937} ERROR - Task failed with exception
Traceback (most recent call last):
  File "/home/petr/project/venv/lib/python3.10/site-packages/airflow/operators/bash.py", line 210, in execute
    raise AirflowException(
airflow.exceptions.AirflowException: Bash command failed. The command returned a non-zero exit code 1.
[2023-11-08T19:48:40.878+0300] {taskinstance.py:1400} INFO - Marking task as FAILED. dag_id=my_task_score, task_id=get_data, execution_date=20231108T164236, start_date=20231108T164829, end_date=20231108T164840
[2023-11-08T19:48:41.013+0300] {standard_task_runner.py:104} ERROR - Failed to execute job 25 for task get_data (Bash command failed. The command returned a non-zero exit code 1.; 36886)
[2023-11-08T19:48:41.097+0300] {local_task_job_runner.py:228} INFO - Task exited with return code 1
[2023-11-08T19:48:41.379+0300] {taskinstance.py:2778} INFO - 0 downstream tasks scheduled from follow-on schedule check
